2020-04-26 14:34:44,174 ERROR: 
            Exception on /check [GET] [in /home/lean/Arhat/venv/lib/python3.7/site-packages/flask/app.py:
            1892]
            
Traceback (most recent call last):
  File "/home/lean/Arhat/venv/lib/python3.7/site-packages/flask/app.py", line 2447, in wsgi_app
    response = self.full_dispatch_request()
  File "/home/lean/Arhat/venv/lib/python3.7/site-packages/flask/app.py", line 1952, in full_dispatch_request
    rv = self.handle_user_exception(e)
  File "/home/lean/Arhat/venv/lib/python3.7/site-packages/flask/app.py", line 1821, in handle_user_exception
    reraise(exc_type, exc_value, tb)
  File "/home/lean/Arhat/venv/lib/python3.7/site-packages/flask/_compat.py", line 39, in reraise
    raise value
  File "/home/lean/Arhat/venv/lib/python3.7/site-packages/flask/app.py", line 1950, in full_dispatch_request
    rv = self.dispatch_request()
  File "/home/lean/Arhat/venv/lib/python3.7/site-packages/flask/app.py", line 1936, in dispatch_request
    return self.view_functions[rule.endpoint](**req.view_args)
  File "/home/lean/Arhat/venv/lib/python3.7/site-packages/flask_login/utils.py", line 272, in decorated_view
    return func(*args, **kwargs)
  File "/home/lean/Arhat/app/main/routes.py", line 199, in check
    f"You need to {task.body}"
AttributeError: 'BaseQuery' object has no attribute 'body'
2020-04-26 14:34:49,175 ERROR: 
            Exception on /check [GET] [in /home/lean/Arhat/venv/lib/python3.7/site-packages/flask/app.py:
            1892]
            
Traceback (most recent call last):
  File "/home/lean/Arhat/venv/lib/python3.7/site-packages/flask/app.py", line 2447, in wsgi_app
    response = self.full_dispatch_request()
  File "/home/lean/Arhat/venv/lib/python3.7/site-packages/flask/app.py", line 1952, in full_dispatch_request
    rv = self.handle_user_exception(e)
  File "/home/lean/Arhat/venv/lib/python3.7/site-packages/flask/app.py", line 1821, in handle_user_exception
    reraise(exc_type, exc_value, tb)
  File "/home/lean/Arhat/venv/lib/python3.7/site-packages/flask/_compat.py", line 39, in reraise
    raise value
  File "/home/lean/Arhat/venv/lib/python3.7/site-packages/flask/app.py", line 1950, in full_dispatch_request
    rv = self.dispatch_request()
  File "/home/lean/Arhat/venv/lib/python3.7/site-packages/flask/app.py", line 1936, in dispatch_request
    return self.view_functions[rule.endpoint](**req.view_args)
  File "/home/lean/Arhat/venv/lib/python3.7/site-packages/flask_login/utils.py", line 272, in decorated_view
    return func(*args, **kwargs)
  File "/home/lean/Arhat/app/main/routes.py", line 199, in check
    f"You need to {task.body}"
AttributeError: 'BaseQuery' object has no attribute 'body'
2020-04-26 14:34:54,173 ERROR: 
            Exception on /check [GET] [in /home/lean/Arhat/venv/lib/python3.7/site-packages/flask/app.py:
            1892]
            
Traceback (most recent call last):
  File "/home/lean/Arhat/venv/lib/python3.7/site-packages/flask/app.py", line 2447, in wsgi_app
    response = self.full_dispatch_request()
  File "/home/lean/Arhat/venv/lib/python3.7/site-packages/flask/app.py", line 1952, in full_dispatch_request
    rv = self.handle_user_exception(e)
  File "/home/lean/Arhat/venv/lib/python3.7/site-packages/flask/app.py", line 1821, in handle_user_exception
    reraise(exc_type, exc_value, tb)
  File "/home/lean/Arhat/venv/lib/python3.7/site-packages/flask/_compat.py", line 39, in reraise
    raise value
  File "/home/lean/Arhat/venv/lib/python3.7/site-packages/flask/app.py", line 1950, in full_dispatch_request
    rv = self.dispatch_request()
  File "/home/lean/Arhat/venv/lib/python3.7/site-packages/flask/app.py", line 1936, in dispatch_request
    return self.view_functions[rule.endpoint](**req.view_args)
  File "/home/lean/Arhat/venv/lib/python3.7/site-packages/flask_login/utils.py", line 272, in decorated_view
    return func(*args, **kwargs)
  File "/home/lean/Arhat/app/main/routes.py", line 199, in check
    f"You need to {task.body}"
AttributeError: 'BaseQuery' object has no attribute 'body'
2020-04-26 14:34:59,170 ERROR: 
            Exception on /check [GET] [in /home/lean/Arhat/venv/lib/python3.7/site-packages/flask/app.py:
            1892]
            
Traceback (most recent call last):
  File "/home/lean/Arhat/venv/lib/python3.7/site-packages/flask/app.py", line 2447, in wsgi_app
    response = self.full_dispatch_request()
  File "/home/lean/Arhat/venv/lib/python3.7/site-packages/flask/app.py", line 1952, in full_dispatch_request
    rv = self.handle_user_exception(e)
  File "/home/lean/Arhat/venv/lib/python3.7/site-packages/flask/app.py", line 1821, in handle_user_exception
    reraise(exc_type, exc_value, tb)
  File "/home/lean/Arhat/venv/lib/python3.7/site-packages/flask/_compat.py", line 39, in reraise
    raise value
  File "/home/lean/Arhat/venv/lib/python3.7/site-packages/flask/app.py", line 1950, in full_dispatch_request
    rv = self.dispatch_request()
  File "/home/lean/Arhat/venv/lib/python3.7/site-packages/flask/app.py", line 1936, in dispatch_request
    return self.view_functions[rule.endpoint](**req.view_args)
  File "/home/lean/Arhat/venv/lib/python3.7/site-packages/flask_login/utils.py", line 272, in decorated_view
    return func(*args, **kwargs)
  File "/home/lean/Arhat/app/main/routes.py", line 199, in check
    f"You need to {task.body}"
AttributeError: 'BaseQuery' object has no attribute 'body'
2020-04-26 14:35:10,253 INFO: 
            Template startup [in /home/lean/Arhat/app/__init__.py:
            91]
            
2020-04-26 14:46:38,836 INFO: 
            Template startup [in /home/lean/Arhat/app/__init__.py:
            91]
            
2020-04-26 17:38:28,102 INFO: 
            Template startup [in /home/lean/Arhat/app/__init__.py:
            91]
            
2020-04-26 17:43:22,283 INFO: 
            Template startup [in /home/lean/Arhat/app/__init__.py:
            91]
            
2020-04-26 17:55:09,959 INFO: 
            Template startup [in /home/lean/Arhat/app/__init__.py:
            91]
            
2020-04-26 17:58:19,943 INFO: 
            Template startup [in /home/lean/Arhat/app/__init__.py:
            91]
            
2020-04-26 18:24:36,235 INFO: 
            Template startup [in /home/lean/Arhat/app/__init__.py:
            91]
            
2020-04-26 18:26:42,388 INFO: 
            Template startup [in /home/lean/Arhat/app/__init__.py:
            91]
            
2020-04-26 18:29:20,401 INFO: 
            Template startup [in /home/lean/Arhat/app/__init__.py:
            91]
            
2020-04-26 18:31:40,567 INFO: 
            Template startup [in /home/lean/Arhat/app/__init__.py:
            91]
            
2020-04-26 18:52:56,435 INFO: 
            Template startup [in /home/lean/Arhat/app/__init__.py:
            91]
            
2020-04-26 18:54:27,256 INFO: 
            Template startup [in /home/lean/Arhat/app/__init__.py:
            91]
            
2020-04-26 18:55:55,207 INFO: 
            Template startup [in /home/lean/Arhat/app/__init__.py:
            91]
            
2020-04-26 19:19:51,113 ERROR: 
            Exception on /update_task/ [POST] [in /home/lean/Arhat/venv/lib/python3.7/site-packages/flask/app.py:
            1892]
            
Traceback (most recent call last):
  File "/home/lean/Arhat/venv/lib/python3.7/site-packages/flask/app.py", line 2447, in wsgi_app
    response = self.full_dispatch_request()
  File "/home/lean/Arhat/venv/lib/python3.7/site-packages/flask/app.py", line 1952, in full_dispatch_request
    rv = self.handle_user_exception(e)
  File "/home/lean/Arhat/venv/lib/python3.7/site-packages/flask/app.py", line 1821, in handle_user_exception
    reraise(exc_type, exc_value, tb)
  File "/home/lean/Arhat/venv/lib/python3.7/site-packages/flask/_compat.py", line 39, in reraise
    raise value
  File "/home/lean/Arhat/venv/lib/python3.7/site-packages/flask/app.py", line 1950, in full_dispatch_request
    rv = self.dispatch_request()
  File "/home/lean/Arhat/venv/lib/python3.7/site-packages/flask/app.py", line 1936, in dispatch_request
    return self.view_functions[rule.endpoint](**req.view_args)
  File "/home/lean/Arhat/venv/lib/python3.7/site-packages/flask_login/utils.py", line 272, in decorated_view
    return func(*args, **kwargs)
  File "/home/lean/Arhat/app/main/routes.py", line 149, in update_task
    height = ''.join([n for n in data['height'] if n.isnumeric()])
TypeError: 'int' object is not iterable
2020-04-26 19:20:26,325 INFO: 
            Template startup [in /home/lean/Arhat/app/__init__.py:
            91]
            
2020-04-26 19:20:30,813 ERROR: 
            Exception on /update_task/ [POST] [in /home/lean/Arhat/venv/lib/python3.7/site-packages/flask/app.py:
            1892]
            
Traceback (most recent call last):
  File "/home/lean/Arhat/venv/lib/python3.7/site-packages/flask/app.py", line 2447, in wsgi_app
    response = self.full_dispatch_request()
  File "/home/lean/Arhat/venv/lib/python3.7/site-packages/flask/app.py", line 1952, in full_dispatch_request
    rv = self.handle_user_exception(e)
  File "/home/lean/Arhat/venv/lib/python3.7/site-packages/flask/app.py", line 1821, in handle_user_exception
    reraise(exc_type, exc_value, tb)
  File "/home/lean/Arhat/venv/lib/python3.7/site-packages/flask/_compat.py", line 39, in reraise
    raise value
  File "/home/lean/Arhat/venv/lib/python3.7/site-packages/flask/app.py", line 1950, in full_dispatch_request
    rv = self.dispatch_request()
  File "/home/lean/Arhat/venv/lib/python3.7/site-packages/flask/app.py", line 1936, in dispatch_request
    return self.view_functions[rule.endpoint](**req.view_args)
  File "/home/lean/Arhat/venv/lib/python3.7/site-packages/flask_login/utils.py", line 272, in decorated_view
    return func(*args, **kwargs)
  File "/home/lean/Arhat/app/main/routes.py", line 153, in update_task
    task.end_time = int(height) + int(top)
ValueError: invalid literal for int() with base 10: ''
2020-04-26 19:22:52,239 INFO: 
            Template startup [in /home/lean/Arhat/app/__init__.py:
            91]
            
