2020-05-31 00:54:38,165 ERROR: 
            Exception on /api/users/tasks/2/31-05-2020 [GET] [in /home/lean/Arhat/venv/lib/python3.7/site-packages/flask/app.py:
            1892]
            
Traceback (most recent call last):
  File "/home/lean/Arhat/venv/lib/python3.7/site-packages/flask/app.py", line 2447, in wsgi_app
    response = self.full_dispatch_request()
  File "/home/lean/Arhat/venv/lib/python3.7/site-packages/flask/app.py", line 1952, in full_dispatch_request
    rv = self.handle_user_exception(e)
  File "/home/lean/Arhat/venv/lib/python3.7/site-packages/flask/app.py", line 1821, in handle_user_exception
    reraise(exc_type, exc_value, tb)
  File "/home/lean/Arhat/venv/lib/python3.7/site-packages/flask/_compat.py", line 39, in reraise
    raise value
  File "/home/lean/Arhat/venv/lib/python3.7/site-packages/flask/app.py", line 1950, in full_dispatch_request
    rv = self.dispatch_request()
  File "/home/lean/Arhat/venv/lib/python3.7/site-packages/flask/app.py", line 1936, in dispatch_request
    return self.view_functions[rule.endpoint](**req.view_args)
  File "/home/lean/Arhat/venv/lib/python3.7/site-packages/flask_httpauth.py", line 162, in decorated
    return f(*args, **kwargs)
  File "/home/lean/Arhat/app/api/users.py", line 102, in tasks
    task['to_date'] = datetime.strftime(task['to_date'], "%d-%m-%Y")
TypeError: descriptor 'strftime' requires a 'datetime.date' object but received a 'NoneType'
2020-05-31 00:56:22,246 INFO: 
            Template startup [in /home/lean/Arhat/app/__init__.py:
            97]
            
2020-05-31 00:56:48,202 INFO: 
            Template startup [in /home/lean/Arhat/app/__init__.py:
            97]
            
2020-05-31 00:58:46,098 ERROR: 
            Exception on /api/users/tasks/591 [PUT] [in /home/lean/Arhat/venv/lib/python3.7/site-packages/flask/app.py:
            1892]
            
Traceback (most recent call last):
  File "/home/lean/Arhat/venv/lib/python3.7/site-packages/flask/app.py", line 2447, in wsgi_app
    response = self.full_dispatch_request()
  File "/home/lean/Arhat/venv/lib/python3.7/site-packages/flask/app.py", line 1952, in full_dispatch_request
    rv = self.handle_user_exception(e)
  File "/home/lean/Arhat/venv/lib/python3.7/site-packages/flask/app.py", line 1821, in handle_user_exception
    reraise(exc_type, exc_value, tb)
  File "/home/lean/Arhat/venv/lib/python3.7/site-packages/flask/_compat.py", line 39, in reraise
    raise value
  File "/home/lean/Arhat/venv/lib/python3.7/site-packages/flask/app.py", line 1950, in full_dispatch_request
    rv = self.dispatch_request()
  File "/home/lean/Arhat/venv/lib/python3.7/site-packages/flask/app.py", line 1936, in dispatch_request
    return self.view_functions[rule.endpoint](**req.view_args)
  File "/home/lean/Arhat/venv/lib/python3.7/site-packages/flask_httpauth.py", line 162, in decorated
    return f(*args, **kwargs)
  File "/home/lean/Arhat/app/api/users.py", line 124, in update_task
    formated_date = datetime.strftime(formated_date, "%Y-%m-%d, 00:00:00")
UnboundLocalError: local variable 'formated_date' referenced before assignment
2020-05-31 00:59:29,360 INFO: 
            Template startup [in /home/lean/Arhat/app/__init__.py:
            97]
            
2020-05-31 00:59:55,407 ERROR: 
            Exception on /api/users/tasks/591 [PUT] [in /home/lean/Arhat/venv/lib/python3.7/site-packages/flask/app.py:
            1892]
            
Traceback (most recent call last):
  File "/home/lean/Arhat/venv/lib/python3.7/site-packages/flask/app.py", line 2447, in wsgi_app
    response = self.full_dispatch_request()
  File "/home/lean/Arhat/venv/lib/python3.7/site-packages/flask/app.py", line 1952, in full_dispatch_request
    rv = self.handle_user_exception(e)
  File "/home/lean/Arhat/venv/lib/python3.7/site-packages/flask/app.py", line 1821, in handle_user_exception
    reraise(exc_type, exc_value, tb)
  File "/home/lean/Arhat/venv/lib/python3.7/site-packages/flask/_compat.py", line 39, in reraise
    raise value
  File "/home/lean/Arhat/venv/lib/python3.7/site-packages/flask/app.py", line 1950, in full_dispatch_request
    rv = self.dispatch_request()
  File "/home/lean/Arhat/venv/lib/python3.7/site-packages/flask/app.py", line 1936, in dispatch_request
    return self.view_functions[rule.endpoint](**req.view_args)
  File "/home/lean/Arhat/venv/lib/python3.7/site-packages/flask_httpauth.py", line 162, in decorated
    return f(*args, **kwargs)
  File "/home/lean/Arhat/app/api/users.py", line 130, in update_task
    if tasks.date == data['date']:
UnboundLocalError: local variable 'tasks' referenced before assignment
2020-05-31 01:00:10,626 INFO: 
            Template startup [in /home/lean/Arhat/app/__init__.py:
            97]
            
2020-05-31 01:00:29,311 ERROR: 
            Exception on /api/users/tasks/590 [PUT] [in /home/lean/Arhat/venv/lib/python3.7/site-packages/flask/app.py:
            1892]
            
Traceback (most recent call last):
  File "/home/lean/Arhat/venv/lib/python3.7/site-packages/flask/app.py", line 2447, in wsgi_app
    response = self.full_dispatch_request()
  File "/home/lean/Arhat/venv/lib/python3.7/site-packages/flask/app.py", line 1952, in full_dispatch_request
    rv = self.handle_user_exception(e)
  File "/home/lean/Arhat/venv/lib/python3.7/site-packages/flask/app.py", line 1821, in handle_user_exception
    reraise(exc_type, exc_value, tb)
  File "/home/lean/Arhat/venv/lib/python3.7/site-packages/flask/_compat.py", line 39, in reraise
    raise value
  File "/home/lean/Arhat/venv/lib/python3.7/site-packages/flask/app.py", line 1950, in full_dispatch_request
    rv = self.dispatch_request()
  File "/home/lean/Arhat/venv/lib/python3.7/site-packages/flask/app.py", line 1936, in dispatch_request
    return self.view_functions[rule.endpoint](**req.view_args)
  File "/home/lean/Arhat/venv/lib/python3.7/site-packages/flask_httpauth.py", line 162, in decorated
    return f(*args, **kwargs)
  File "/home/lean/Arhat/app/api/users.py", line 130, in update_task
    if tasks.date == data['date']:
UnboundLocalError: local variable 'tasks' referenced before assignment
2020-05-31 01:00:31,418 ERROR: 
            Exception on /api/users/tasks/590 [PUT] [in /home/lean/Arhat/venv/lib/python3.7/site-packages/flask/app.py:
            1892]
            
Traceback (most recent call last):
  File "/home/lean/Arhat/venv/lib/python3.7/site-packages/flask/app.py", line 2447, in wsgi_app
    response = self.full_dispatch_request()
  File "/home/lean/Arhat/venv/lib/python3.7/site-packages/flask/app.py", line 1952, in full_dispatch_request
    rv = self.handle_user_exception(e)
  File "/home/lean/Arhat/venv/lib/python3.7/site-packages/flask/app.py", line 1821, in handle_user_exception
    reraise(exc_type, exc_value, tb)
  File "/home/lean/Arhat/venv/lib/python3.7/site-packages/flask/_compat.py", line 39, in reraise
    raise value
  File "/home/lean/Arhat/venv/lib/python3.7/site-packages/flask/app.py", line 1950, in full_dispatch_request
    rv = self.dispatch_request()
  File "/home/lean/Arhat/venv/lib/python3.7/site-packages/flask/app.py", line 1936, in dispatch_request
    return self.view_functions[rule.endpoint](**req.view_args)
  File "/home/lean/Arhat/venv/lib/python3.7/site-packages/flask_httpauth.py", line 162, in decorated
    return f(*args, **kwargs)
  File "/home/lean/Arhat/app/api/users.py", line 130, in update_task
    if tasks.date == data['date']:
UnboundLocalError: local variable 'tasks' referenced before assignment
2020-05-31 01:01:18,573 INFO: 
            Template startup [in /home/lean/Arhat/app/__init__.py:
            97]
            
2020-05-31 01:01:20,477 ERROR: 
            Exception on /api/users/tasks/590 [PUT] [in /home/lean/Arhat/venv/lib/python3.7/site-packages/flask/app.py:
            1892]
            
Traceback (most recent call last):
  File "/home/lean/Arhat/venv/lib/python3.7/site-packages/flask/app.py", line 2447, in wsgi_app
    response = self.full_dispatch_request()
  File "/home/lean/Arhat/venv/lib/python3.7/site-packages/flask/app.py", line 1952, in full_dispatch_request
    rv = self.handle_user_exception(e)
  File "/home/lean/Arhat/venv/lib/python3.7/site-packages/flask/app.py", line 1821, in handle_user_exception
    reraise(exc_type, exc_value, tb)
  File "/home/lean/Arhat/venv/lib/python3.7/site-packages/flask/_compat.py", line 39, in reraise
    raise value
  File "/home/lean/Arhat/venv/lib/python3.7/site-packages/flask/app.py", line 1950, in full_dispatch_request
    rv = self.dispatch_request()
  File "/home/lean/Arhat/venv/lib/python3.7/site-packages/flask/app.py", line 1936, in dispatch_request
    return self.view_functions[rule.endpoint](**req.view_args)
  File "/home/lean/Arhat/venv/lib/python3.7/site-packages/flask_httpauth.py", line 162, in decorated
    return f(*args, **kwargs)
  File "/home/lean/Arhat/app/api/users.py", line 130, in update_task
    if task.date == data['date']:
KeyError: 'date'
2020-05-31 01:01:51,495 INFO: 
            Template startup [in /home/lean/Arhat/app/__init__.py:
            97]
            
2020-05-31 01:02:42,337 INFO: 
            Template startup [in /home/lean/Arhat/app/__init__.py:
            97]
            
2020-05-31 12:48:35,048 INFO: 
            Template startup [in /home/lean/Arhat/app/__init__.py:
            97]
            
