2020-05-03 14:17:18,090 ERROR: 
            Exception on /follow_request/test99 [GET] [in /home/lean/Arhat/venv/lib/python3.7/site-packages/flask/app.py:
            1892]
            
Traceback (most recent call last):
  File "/home/lean/Arhat/venv/lib/python3.7/site-packages/flask/app.py", line 2447, in wsgi_app
    response = self.full_dispatch_request()
  File "/home/lean/Arhat/venv/lib/python3.7/site-packages/flask/app.py", line 1952, in full_dispatch_request
    rv = self.handle_user_exception(e)
  File "/home/lean/Arhat/venv/lib/python3.7/site-packages/flask/app.py", line 1821, in handle_user_exception
    reraise(exc_type, exc_value, tb)
  File "/home/lean/Arhat/venv/lib/python3.7/site-packages/flask/_compat.py", line 39, in reraise
    raise value
  File "/home/lean/Arhat/venv/lib/python3.7/site-packages/flask/app.py", line 1950, in full_dispatch_request
    rv = self.dispatch_request()
  File "/home/lean/Arhat/venv/lib/python3.7/site-packages/flask/app.py", line 1936, in dispatch_request
    return self.view_functions[rule.endpoint](**req.view_args)
  File "/home/lean/Arhat/venv/lib/python3.7/site-packages/flask_login/utils.py", line 272, in decorated_view
    return func(*args, **kwargs)
  File "/home/lean/Arhat/app/sn/routes.py", line 198, in follow_request
    token=token
  File "/home/lean/Arhat/venv/lib/python3.7/site-packages/flask/templating.py", line 140, in render_template
    ctx.app,
  File "/home/lean/Arhat/venv/lib/python3.7/site-packages/flask/templating.py", line 120, in _render
    rv = template.render(context)
  File "/home/lean/Arhat/venv/lib/python3.7/site-packages/jinja2/environment.py", line 1090, in render
    self.environment.handle_exception()
  File "/home/lean/Arhat/venv/lib/python3.7/site-packages/jinja2/environment.py", line 832, in handle_exception
    reraise(*rewrite_traceback_stack(source=source))
  File "/home/lean/Arhat/venv/lib/python3.7/site-packages/jinja2/_compat.py", line 28, in reraise
    raise value.with_traceback(tb)
  File "/home/lean/Arhat/app/templates/email/follow_request.html", line 4, in top-level template code
    <a href="{{ url_for('main.follow', username=user.username, follow_requester=follow_requester.username, token=token, _external=True) }}">
  File "/home/lean/Arhat/venv/lib/python3.7/site-packages/flask/helpers.py", line 370, in url_for
    return appctx.app.handle_url_build_error(error, endpoint, values)
  File "/home/lean/Arhat/venv/lib/python3.7/site-packages/flask/app.py", line 2216, in handle_url_build_error
    reraise(exc_type, exc_value, tb)
  File "/home/lean/Arhat/venv/lib/python3.7/site-packages/flask/_compat.py", line 39, in reraise
    raise value
  File "/home/lean/Arhat/venv/lib/python3.7/site-packages/flask/helpers.py", line 358, in url_for
    endpoint, values, method=method, force_external=external
  File "/home/lean/Arhat/venv/lib/python3.7/site-packages/werkzeug/routing.py", line 2179, in build
    raise BuildError(endpoint, values, method, self)
werkzeug.routing.BuildError: Could not build url for endpoint 'main.follow' with values ['follow_requester', 'token', 'username']. Did you mean 'sn.follow' instead?
2020-05-03 14:17:38,807 ERROR: 
            Exception on /follow_request/test99 [GET] [in /home/lean/Arhat/venv/lib/python3.7/site-packages/flask/app.py:
            1892]
            
Traceback (most recent call last):
  File "/home/lean/Arhat/venv/lib/python3.7/site-packages/flask/app.py", line 2447, in wsgi_app
    response = self.full_dispatch_request()
  File "/home/lean/Arhat/venv/lib/python3.7/site-packages/flask/app.py", line 1952, in full_dispatch_request
    rv = self.handle_user_exception(e)
  File "/home/lean/Arhat/venv/lib/python3.7/site-packages/flask/app.py", line 1821, in handle_user_exception
    reraise(exc_type, exc_value, tb)
  File "/home/lean/Arhat/venv/lib/python3.7/site-packages/flask/_compat.py", line 39, in reraise
    raise value
  File "/home/lean/Arhat/venv/lib/python3.7/site-packages/flask/app.py", line 1950, in full_dispatch_request
    rv = self.dispatch_request()
  File "/home/lean/Arhat/venv/lib/python3.7/site-packages/flask/app.py", line 1936, in dispatch_request
    return self.view_functions[rule.endpoint](**req.view_args)
  File "/home/lean/Arhat/venv/lib/python3.7/site-packages/flask_login/utils.py", line 272, in decorated_view
    return func(*args, **kwargs)
  File "/home/lean/Arhat/app/sn/routes.py", line 198, in follow_request
    token=token
  File "/home/lean/Arhat/venv/lib/python3.7/site-packages/flask/templating.py", line 140, in render_template
    ctx.app,
  File "/home/lean/Arhat/venv/lib/python3.7/site-packages/flask/templating.py", line 120, in _render
    rv = template.render(context)
  File "/home/lean/Arhat/venv/lib/python3.7/site-packages/jinja2/environment.py", line 1090, in render
    self.environment.handle_exception()
  File "/home/lean/Arhat/venv/lib/python3.7/site-packages/jinja2/environment.py", line 832, in handle_exception
    reraise(*rewrite_traceback_stack(source=source))
  File "/home/lean/Arhat/venv/lib/python3.7/site-packages/jinja2/_compat.py", line 28, in reraise
    raise value.with_traceback(tb)
  File "/home/lean/Arhat/app/templates/email/follow_request.html", line 4, in top-level template code
    <a href="{{ url_for('main.follow', username=user.username, follow_requester=follow_requester.username, token=token, _external=True) }}">
  File "/home/lean/Arhat/venv/lib/python3.7/site-packages/flask/helpers.py", line 370, in url_for
    return appctx.app.handle_url_build_error(error, endpoint, values)
  File "/home/lean/Arhat/venv/lib/python3.7/site-packages/flask/app.py", line 2216, in handle_url_build_error
    reraise(exc_type, exc_value, tb)
  File "/home/lean/Arhat/venv/lib/python3.7/site-packages/flask/_compat.py", line 39, in reraise
    raise value
  File "/home/lean/Arhat/venv/lib/python3.7/site-packages/flask/helpers.py", line 358, in url_for
    endpoint, values, method=method, force_external=external
  File "/home/lean/Arhat/venv/lib/python3.7/site-packages/werkzeug/routing.py", line 2179, in build
    raise BuildError(endpoint, values, method, self)
werkzeug.routing.BuildError: Could not build url for endpoint 'main.follow' with values ['follow_requester', 'token', 'username']. Did you mean 'sn.follow' instead?
2020-05-03 14:21:13,986 ERROR: 
            Exception on /follow_request/test10 [GET] [in /home/lean/Arhat/venv/lib/python3.7/site-packages/flask/app.py:
            1892]
            
Traceback (most recent call last):
  File "/home/lean/Arhat/venv/lib/python3.7/site-packages/flask/app.py", line 2447, in wsgi_app
    response = self.full_dispatch_request()
  File "/home/lean/Arhat/venv/lib/python3.7/site-packages/flask/app.py", line 1952, in full_dispatch_request
    rv = self.handle_user_exception(e)
  File "/home/lean/Arhat/venv/lib/python3.7/site-packages/flask/app.py", line 1821, in handle_user_exception
    reraise(exc_type, exc_value, tb)
  File "/home/lean/Arhat/venv/lib/python3.7/site-packages/flask/_compat.py", line 39, in reraise
    raise value
  File "/home/lean/Arhat/venv/lib/python3.7/site-packages/flask/app.py", line 1950, in full_dispatch_request
    rv = self.dispatch_request()
  File "/home/lean/Arhat/venv/lib/python3.7/site-packages/flask/app.py", line 1936, in dispatch_request
    return self.view_functions[rule.endpoint](**req.view_args)
  File "/home/lean/Arhat/venv/lib/python3.7/site-packages/flask_login/utils.py", line 272, in decorated_view
    return func(*args, **kwargs)
  File "/home/lean/Arhat/app/sn/routes.py", line 198, in follow_request
    token=token
  File "/home/lean/Arhat/venv/lib/python3.7/site-packages/flask/templating.py", line 140, in render_template
    ctx.app,
  File "/home/lean/Arhat/venv/lib/python3.7/site-packages/flask/templating.py", line 120, in _render
    rv = template.render(context)
  File "/home/lean/Arhat/venv/lib/python3.7/site-packages/jinja2/environment.py", line 1090, in render
    self.environment.handle_exception()
  File "/home/lean/Arhat/venv/lib/python3.7/site-packages/jinja2/environment.py", line 832, in handle_exception
    reraise(*rewrite_traceback_stack(source=source))
  File "/home/lean/Arhat/venv/lib/python3.7/site-packages/jinja2/_compat.py", line 28, in reraise
    raise value.with_traceback(tb)
  File "/home/lean/Arhat/app/templates/email/follow_request.html", line 4, in top-level template code
    <a href="{{ url_for('sn.follow', username=user.username, follow_requester=follow_requester.username, token=token, _external=True) }}">
  File "/home/lean/Arhat/venv/lib/python3.7/site-packages/flask/helpers.py", line 370, in url_for
    return appctx.app.handle_url_build_error(error, endpoint, values)
  File "/home/lean/Arhat/venv/lib/python3.7/site-packages/flask/app.py", line 2216, in handle_url_build_error
    reraise(exc_type, exc_value, tb)
  File "/home/lean/Arhat/venv/lib/python3.7/site-packages/flask/_compat.py", line 39, in reraise
    raise value
  File "/home/lean/Arhat/venv/lib/python3.7/site-packages/flask/helpers.py", line 358, in url_for
    endpoint, values, method=method, force_external=external
  File "/home/lean/Arhat/venv/lib/python3.7/site-packages/werkzeug/routing.py", line 2179, in build
    raise BuildError(endpoint, values, method, self)
werkzeug.routing.BuildError: Could not build url for endpoint 'main.follow' with values ['follow_requester', 'token', 'username']. Did you mean 'sn.follow' instead?
2020-05-03 14:21:24,696 INFO: 
            Template startup [in /home/lean/Arhat/app/__init__.py:
            91]
            
2020-05-05 20:59:19,606 INFO: 
            Template startup [in /home/lean/Arhat/app/__init__.py:
            91]
            
2020-05-06 22:12:20,218 INFO: 
            Template startup [in /home/lean/Arhat/app/__init__.py:
            91]
            
