2020-05-01 14:37:49,864 ERROR: 
            Exception on /contacts [POST] [in /home/lean/Arhat/venv/lib/python3.7/site-packages/flask/app.py:
            1892]
            
Traceback (most recent call last):
  File "/home/lean/Arhat/venv/lib/python3.7/site-packages/flask/app.py", line 2447, in wsgi_app
    response = self.full_dispatch_request()
  File "/home/lean/Arhat/venv/lib/python3.7/site-packages/flask/app.py", line 1952, in full_dispatch_request
    rv = self.handle_user_exception(e)
  File "/home/lean/Arhat/venv/lib/python3.7/site-packages/flask/app.py", line 1821, in handle_user_exception
    reraise(exc_type, exc_value, tb)
  File "/home/lean/Arhat/venv/lib/python3.7/site-packages/flask/_compat.py", line 39, in reraise
    raise value
  File "/home/lean/Arhat/venv/lib/python3.7/site-packages/flask/app.py", line 1950, in full_dispatch_request
    rv = self.dispatch_request()
  File "/home/lean/Arhat/venv/lib/python3.7/site-packages/flask/app.py", line 1936, in dispatch_request
    return self.view_functions[rule.endpoint](**req.view_args)
  File "/home/lean/Arhat/venv/lib/python3.7/site-packages/flask_login/utils.py", line 272, in decorated_view
    return func(*args, **kwargs)
  File "/home/lean/Arhat/app/sn/routes.py", line 130, in contacts
    if people.has_next else None
AttributeError: 'list' object has no attribute 'has_next'
2020-05-01 14:40:32,647 INFO: 
            Template startup [in /home/lean/Arhat/app/__init__.py:
            91]
            
2020-05-01 14:40:40,892 ERROR: 
            Exception on /contacts [POST] [in /home/lean/Arhat/venv/lib/python3.7/site-packages/flask/app.py:
            1892]
            
Traceback (most recent call last):
  File "/home/lean/Arhat/venv/lib/python3.7/site-packages/flask/app.py", line 2447, in wsgi_app
    response = self.full_dispatch_request()
  File "/home/lean/Arhat/venv/lib/python3.7/site-packages/flask/app.py", line 1952, in full_dispatch_request
    rv = self.handle_user_exception(e)
  File "/home/lean/Arhat/venv/lib/python3.7/site-packages/flask/app.py", line 1821, in handle_user_exception
    reraise(exc_type, exc_value, tb)
  File "/home/lean/Arhat/venv/lib/python3.7/site-packages/flask/_compat.py", line 39, in reraise
    raise value
  File "/home/lean/Arhat/venv/lib/python3.7/site-packages/flask/app.py", line 1950, in full_dispatch_request
    rv = self.dispatch_request()
  File "/home/lean/Arhat/venv/lib/python3.7/site-packages/flask/app.py", line 1936, in dispatch_request
    return self.view_functions[rule.endpoint](**req.view_args)
  File "/home/lean/Arhat/venv/lib/python3.7/site-packages/flask_login/utils.py", line 272, in decorated_view
    return func(*args, **kwargs)
  File "/home/lean/Arhat/app/sn/routes.py", line 138, in contacts
    people=people.items,
AttributeError: 'list' object has no attribute 'items'
2020-05-01 14:41:09,488 INFO: 
            Template startup [in /home/lean/Arhat/app/__init__.py:
            91]
            
2020-05-01 14:41:11,255 ERROR: 
            Exception on /contacts [GET] [in /home/lean/Arhat/venv/lib/python3.7/site-packages/flask/app.py:
            1892]
            
Traceback (most recent call last):
  File "/home/lean/Arhat/venv/lib/python3.7/site-packages/flask/app.py", line 2447, in wsgi_app
    response = self.full_dispatch_request()
  File "/home/lean/Arhat/venv/lib/python3.7/site-packages/flask/app.py", line 1952, in full_dispatch_request
    rv = self.handle_user_exception(e)
  File "/home/lean/Arhat/venv/lib/python3.7/site-packages/flask/app.py", line 1821, in handle_user_exception
    reraise(exc_type, exc_value, tb)
  File "/home/lean/Arhat/venv/lib/python3.7/site-packages/flask/_compat.py", line 39, in reraise
    raise value
  File "/home/lean/Arhat/venv/lib/python3.7/site-packages/flask/app.py", line 1950, in full_dispatch_request
    rv = self.dispatch_request()
  File "/home/lean/Arhat/venv/lib/python3.7/site-packages/flask/app.py", line 1936, in dispatch_request
    return self.view_functions[rule.endpoint](**req.view_args)
  File "/home/lean/Arhat/venv/lib/python3.7/site-packages/flask_login/utils.py", line 272, in decorated_view
    return func(*args, **kwargs)
  File "/home/lean/Arhat/app/sn/routes.py", line 132, in contacts
    if people.has_next:
AttributeError: 'list' object has no attribute 'has_next'
2020-05-01 14:41:27,578 INFO: 
            Template startup [in /home/lean/Arhat/app/__init__.py:
            91]
            
2020-05-01 14:41:29,292 ERROR: 
            Exception on /contacts [GET] [in /home/lean/Arhat/venv/lib/python3.7/site-packages/flask/app.py:
            1892]
            
Traceback (most recent call last):
  File "/home/lean/Arhat/venv/lib/python3.7/site-packages/flask/app.py", line 2447, in wsgi_app
    response = self.full_dispatch_request()
  File "/home/lean/Arhat/venv/lib/python3.7/site-packages/flask/app.py", line 1952, in full_dispatch_request
    rv = self.handle_user_exception(e)
  File "/home/lean/Arhat/venv/lib/python3.7/site-packages/flask/app.py", line 1821, in handle_user_exception
    reraise(exc_type, exc_value, tb)
  File "/home/lean/Arhat/venv/lib/python3.7/site-packages/flask/_compat.py", line 39, in reraise
    raise value
  File "/home/lean/Arhat/venv/lib/python3.7/site-packages/flask/app.py", line 1950, in full_dispatch_request
    rv = self.dispatch_request()
  File "/home/lean/Arhat/venv/lib/python3.7/site-packages/flask/app.py", line 1936, in dispatch_request
    return self.view_functions[rule.endpoint](**req.view_args)
  File "/home/lean/Arhat/venv/lib/python3.7/site-packages/flask_login/utils.py", line 272, in decorated_view
    return func(*args, **kwargs)
  File "/home/lean/Arhat/app/sn/routes.py", line 139, in contacts
    people=people.items,
AttributeError: 'list' object has no attribute 'items'
2020-05-01 14:41:46,632 INFO: 
            Template startup [in /home/lean/Arhat/app/__init__.py:
            91]
            
2020-05-01 14:54:09,390 INFO: 
            Template startup [in /home/lean/Arhat/app/__init__.py:
            91]
            
