2020-06-03 22:21:02,556 ERROR: 
            Exception on /login/callback [GET] [in /home/lean/Arhat/venv/lib/python3.7/site-packages/flask/app.py:
            1892]
            
Traceback (most recent call last):
  File "/home/lean/Arhat/venv/lib/python3.7/site-packages/flask/app.py", line 2447, in wsgi_app
    response = self.full_dispatch_request()
  File "/home/lean/Arhat/venv/lib/python3.7/site-packages/flask/app.py", line 1952, in full_dispatch_request
    rv = self.handle_user_exception(e)
  File "/home/lean/Arhat/venv/lib/python3.7/site-packages/flask/app.py", line 1821, in handle_user_exception
    reraise(exc_type, exc_value, tb)
  File "/home/lean/Arhat/venv/lib/python3.7/site-packages/flask/_compat.py", line 39, in reraise
    raise value
  File "/home/lean/Arhat/venv/lib/python3.7/site-packages/flask/app.py", line 1950, in full_dispatch_request
    rv = self.dispatch_request()
  File "/home/lean/Arhat/venv/lib/python3.7/site-packages/flask/app.py", line 1936, in dispatch_request
    return self.view_functions[rule.endpoint](**req.view_args)
  File "/home/lean/Arhat/app/auth/routes.py", line 165, in callback
    json.dumps(token_response.json())
  File "/home/lean/Arhat/venv/lib/python3.7/site-packages/oauthlib/oauth2/rfc6749/clients/base.py", line 421, in parse_request_body_response
    self.token = parse_token_response(body, scope=scope)
  File "/home/lean/Arhat/venv/lib/python3.7/site-packages/oauthlib/oauth2/rfc6749/parameters.py", line 431, in parse_token_response
    validate_token_parameters(params)
  File "/home/lean/Arhat/venv/lib/python3.7/site-packages/oauthlib/oauth2/rfc6749/parameters.py", line 438, in validate_token_parameters
    raise_from_error(params.get('error'), params)
  File "/home/lean/Arhat/venv/lib/python3.7/site-packages/oauthlib/oauth2/rfc6749/errors.py", line 405, in raise_from_error
    raise cls(**kwargs)
oauthlib.oauth2.rfc6749.errors.UnauthorizedClientError: (unauthorized_client) Unauthorized
2020-06-03 22:26:10,127 INFO: 
            Template startup [in /home/lean/Arhat/app/__init__.py:
            97]
            
2020-06-03 23:14:11,483 INFO: 
            Template startup [in /home/lean/Arhat/app/__init__.py:
            97]
            
2020-06-03 23:15:14,550 INFO: 
            Template startup [in /home/lean/Arhat/app/__init__.py:
            97]
            
2020-06-03 23:30:04,908 INFO: 
            Template startup [in /home/lean/Arhat/app/__init__.py:
            97]
            
2020-06-04 00:26:06,123 INFO: 
            Template startup [in /home/lean/Arhat/app/__init__.py:
            97]
            
2020-06-04 00:26:31,221 ERROR: 
            Exception on /login/callback [GET] [in /home/lean/Arhat/venv/lib/python3.7/site-packages/flask/app.py:
            1892]
            
Traceback (most recent call last):
  File "/home/lean/Arhat/venv/lib/python3.7/site-packages/flask/app.py", line 2447, in wsgi_app
    response = self.full_dispatch_request()
  File "/home/lean/Arhat/venv/lib/python3.7/site-packages/flask/app.py", line 1952, in full_dispatch_request
    rv = self.handle_user_exception(e)
  File "/home/lean/Arhat/venv/lib/python3.7/site-packages/flask/app.py", line 1821, in handle_user_exception
    reraise(exc_type, exc_value, tb)
  File "/home/lean/Arhat/venv/lib/python3.7/site-packages/flask/_compat.py", line 39, in reraise
    raise value
  File "/home/lean/Arhat/venv/lib/python3.7/site-packages/flask/app.py", line 1950, in full_dispatch_request
    rv = self.dispatch_request()
  File "/home/lean/Arhat/venv/lib/python3.7/site-packages/flask/app.py", line 1936, in dispatch_request
    return self.view_functions[rule.endpoint](**req.view_args)
  File "/home/lean/Arhat/app/auth/routes.py", line 154, in callback
    code=code
  File "/home/lean/Arhat/venv/lib/python3.7/site-packages/oauthlib/oauth2/rfc6749/clients/base.py", line 275, in prepare_token_request
    authorization_response, state=state)
  File "/home/lean/Arhat/venv/lib/python3.7/site-packages/oauthlib/oauth2/rfc6749/clients/web_application.py", line 203, in parse_request_uri_response
    response = parse_authorization_code_response(uri, state=state)
  File "/home/lean/Arhat/venv/lib/python3.7/site-packages/oauthlib/oauth2/rfc6749/parameters.py", line 262, in parse_authorization_code_response
    raise InsecureTransportError()
oauthlib.oauth2.rfc6749.errors.InsecureTransportError: (insecure_transport) OAuth 2 MUST utilize https.
2020-06-04 15:45:14,208 INFO: 
            Template startup [in /home/lean/Arhat/app/__init__.py:
            97]
            
2020-06-04 15:47:25,142 INFO: 
            Template startup [in /home/lean/Arhat/app/__init__.py:
            97]
            
2020-06-04 15:48:53,967 INFO: 
            Template startup [in /home/lean/Arhat/app/__init__.py:
            97]
            
2020-06-04 15:50:31,972 INFO: 
            Template startup [in /home/lean/Arhat/app/__init__.py:
            97]
            
2020-06-04 15:52:55,831 INFO: 
            Template startup [in /home/lean/Arhat/app/__init__.py:
            97]
            
2020-06-04 15:54:01,956 INFO: 
            Template startup [in /home/lean/Arhat/app/__init__.py:
            97]
            
2020-06-04 15:58:51,545 INFO: 
            Template startup [in /home/lean/Arhat/app/__init__.py:
            97]
            
2020-06-04 16:20:33,017 INFO: 
            Template startup [in /home/lean/Arhat/app/__init__.py:
            97]
            
