2020-05-30 14:39:41,254 ERROR: 
            Exception on /api/users/tasks/2/30-05-2020 [POST] [in /home/lean/Arhat/venv/lib/python3.7/site-packages/flask/app.py:
            1892]
            
Traceback (most recent call last):
  File "/home/lean/Arhat/venv/lib/python3.7/site-packages/flask/app.py", line 2447, in wsgi_app
    response = self.full_dispatch_request()
  File "/home/lean/Arhat/venv/lib/python3.7/site-packages/flask/app.py", line 1952, in full_dispatch_request
    rv = self.handle_user_exception(e)
  File "/home/lean/Arhat/venv/lib/python3.7/site-packages/flask/app.py", line 1821, in handle_user_exception
    reraise(exc_type, exc_value, tb)
  File "/home/lean/Arhat/venv/lib/python3.7/site-packages/flask/_compat.py", line 39, in reraise
    raise value
  File "/home/lean/Arhat/venv/lib/python3.7/site-packages/flask/app.py", line 1950, in full_dispatch_request
    rv = self.dispatch_request()
  File "/home/lean/Arhat/venv/lib/python3.7/site-packages/flask/app.py", line 1936, in dispatch_request
    return self.view_functions[rule.endpoint](**req.view_args)
  File "/home/lean/Arhat/app/api/users.py", line 123, in create_task
    task.from_dict(data)
  File "/home/lean/Arhat/app/models.py", line 523, in from_dict
    data['to_date'] = datetime.strptime(date, "%d-%m-%Y, %H:%M:%S")
  File "/usr/lib/python3.7/_strptime.py", line 577, in _strptime_datetime
    tt, fraction, gmtoff_fraction = _strptime(data_string, format)
  File "/usr/lib/python3.7/_strptime.py", line 359, in _strptime
    (data_string, format))
ValueError: time data '2020-05-31, 00:00:00' does not match format '%d-%m-%Y, %H:%M:%S'
2020-05-30 14:40:10,303 INFO: 
            Template startup [in /home/lean/Arhat/app/__init__.py:
            97]
            
2020-05-30 15:41:04,828 INFO: 
            Template startup [in /home/lean/Arhat/app/__init__.py:
            97]
            
2020-05-30 15:41:31,558 ERROR: 
            Exception on /new_task/ [POST] [in /home/lean/Arhat/venv/lib/python3.7/site-packages/flask/app.py:
            1892]
            
Traceback (most recent call last):
  File "/home/lean/Arhat/venv/lib/python3.7/site-packages/flask/app.py", line 2447, in wsgi_app
    response = self.full_dispatch_request()
  File "/home/lean/Arhat/venv/lib/python3.7/site-packages/flask/app.py", line 1952, in full_dispatch_request
    rv = self.handle_user_exception(e)
  File "/home/lean/Arhat/venv/lib/python3.7/site-packages/flask/app.py", line 1821, in handle_user_exception
    reraise(exc_type, exc_value, tb)
  File "/home/lean/Arhat/venv/lib/python3.7/site-packages/flask/_compat.py", line 39, in reraise
    raise value
  File "/home/lean/Arhat/venv/lib/python3.7/site-packages/flask/app.py", line 1950, in full_dispatch_request
    rv = self.dispatch_request()
  File "/home/lean/Arhat/venv/lib/python3.7/site-packages/flask/app.py", line 1936, in dispatch_request
    return self.view_functions[rule.endpoint](**req.view_args)
  File "/home/lean/Arhat/venv/lib/python3.7/site-packages/flask_login/utils.py", line 272, in decorated_view
    return func(*args, **kwargs)
  File "/home/lean/Arhat/app/main/routes.py", line 94, in new_task
    new_task.add_multiple_tasks()
  File "/home/lean/Arhat/app/models.py", line 560, in add_multiple_tasks
    for self.i in range((self.to_date - self.date).days, -1, -self.frequency):
TypeError: bad operand type for unary -: 'NoneType'
2020-05-30 15:43:28,933 INFO: 
            Template startup [in /home/lean/Arhat/app/__init__.py:
            97]
            
2020-05-30 15:44:08,053 ERROR: 
            Exception on /new_task/ [POST] [in /home/lean/Arhat/venv/lib/python3.7/site-packages/flask/app.py:
            1892]
            
Traceback (most recent call last):
  File "/home/lean/Arhat/venv/lib/python3.7/site-packages/flask/app.py", line 2447, in wsgi_app
    response = self.full_dispatch_request()
  File "/home/lean/Arhat/venv/lib/python3.7/site-packages/flask/app.py", line 1952, in full_dispatch_request
    rv = self.handle_user_exception(e)
  File "/home/lean/Arhat/venv/lib/python3.7/site-packages/flask/app.py", line 1821, in handle_user_exception
    reraise(exc_type, exc_value, tb)
  File "/home/lean/Arhat/venv/lib/python3.7/site-packages/flask/_compat.py", line 39, in reraise
    raise value
  File "/home/lean/Arhat/venv/lib/python3.7/site-packages/flask/app.py", line 1950, in full_dispatch_request
    rv = self.dispatch_request()
  File "/home/lean/Arhat/venv/lib/python3.7/site-packages/flask/app.py", line 1936, in dispatch_request
    return self.view_functions[rule.endpoint](**req.view_args)
  File "/home/lean/Arhat/venv/lib/python3.7/site-packages/flask_login/utils.py", line 272, in decorated_view
    return func(*args, **kwargs)
  File "/home/lean/Arhat/app/main/routes.py", line 94, in new_task
    new_task.add_multiple_tasks()
  File "/home/lean/Arhat/app/models.py", line 560, in add_multiple_tasks
    for self.i in range((self.to_date - self.date).days, -1, self.frequency*-1):
TypeError: unsupported operand type(s) for *: 'NoneType' and 'int'
2020-05-30 15:45:13,012 INFO: 
            Template startup [in /home/lean/Arhat/app/__init__.py:
            97]
            
2020-05-30 16:00:02,438 INFO: 
            Template startup [in /home/lean/Arhat/app/__init__.py:
            97]
            
2020-05-30 17:24:44,593 INFO: 
            Template startup [in /home/lean/Arhat/app/__init__.py:
            97]
            
2020-05-30 17:25:37,682 ERROR: 
            Exception on /api/users/tasks/2/30-05-2020 [POST] [in /home/lean/Arhat/venv/lib/python3.7/site-packages/flask/app.py:
            1892]
            
Traceback (most recent call last):
  File "/home/lean/Arhat/venv/lib/python3.7/site-packages/flask/app.py", line 2447, in wsgi_app
    response = self.full_dispatch_request()
  File "/home/lean/Arhat/venv/lib/python3.7/site-packages/flask/app.py", line 1952, in full_dispatch_request
    rv = self.handle_user_exception(e)
  File "/home/lean/Arhat/venv/lib/python3.7/site-packages/flask/app.py", line 1821, in handle_user_exception
    reraise(exc_type, exc_value, tb)
  File "/home/lean/Arhat/venv/lib/python3.7/site-packages/flask/_compat.py", line 39, in reraise
    raise value
  File "/home/lean/Arhat/venv/lib/python3.7/site-packages/flask/app.py", line 1950, in full_dispatch_request
    rv = self.dispatch_request()
  File "/home/lean/Arhat/venv/lib/python3.7/site-packages/flask/app.py", line 1936, in dispatch_request
    return self.view_functions[rule.endpoint](**req.view_args)
  File "/home/lean/Arhat/app/api/users.py", line 139, in create_task
    for i in range(0, frequency_days, inc):
ValueError: range() arg 3 must not be zero
2020-05-30 17:26:00,748 INFO: 
            Template startup [in /home/lean/Arhat/app/__init__.py:
            97]
            
2020-05-30 17:26:27,462 ERROR: 
            Exception on /api/users/tasks/2/30-05-2020 [POST] [in /home/lean/Arhat/venv/lib/python3.7/site-packages/flask/app.py:
            1892]
            
Traceback (most recent call last):
  File "/home/lean/Arhat/venv/lib/python3.7/site-packages/flask/app.py", line 2447, in wsgi_app
    response = self.full_dispatch_request()
  File "/home/lean/Arhat/venv/lib/python3.7/site-packages/flask/app.py", line 1952, in full_dispatch_request
    rv = self.handle_user_exception(e)
  File "/home/lean/Arhat/venv/lib/python3.7/site-packages/flask/app.py", line 1821, in handle_user_exception
    reraise(exc_type, exc_value, tb)
  File "/home/lean/Arhat/venv/lib/python3.7/site-packages/flask/_compat.py", line 39, in reraise
    raise value
  File "/home/lean/Arhat/venv/lib/python3.7/site-packages/flask/app.py", line 1950, in full_dispatch_request
    rv = self.dispatch_request()
  File "/home/lean/Arhat/venv/lib/python3.7/site-packages/flask/app.py", line 1936, in dispatch_request
    return self.view_functions[rule.endpoint](**req.view_args)
  File "/home/lean/Arhat/app/api/users.py", line 140, in create_task
    data['date'] = data['date'] + timedelta(days=i)
NameError: name 'timedelta' is not defined
2020-05-30 17:27:14,048 INFO: 
            Template startup [in /home/lean/Arhat/app/__init__.py:
            97]
            
2020-05-30 17:28:56,017 ERROR: 
            Exception on /api/users/tasks/2/30-05-2020 [POST] [in /home/lean/Arhat/venv/lib/python3.7/site-packages/flask/app.py:
            1892]
            
Traceback (most recent call last):
  File "/home/lean/Arhat/venv/lib/python3.7/site-packages/flask/app.py", line 2447, in wsgi_app
    response = self.full_dispatch_request()
  File "/home/lean/Arhat/venv/lib/python3.7/site-packages/flask/app.py", line 1952, in full_dispatch_request
    rv = self.handle_user_exception(e)
  File "/home/lean/Arhat/venv/lib/python3.7/site-packages/flask/app.py", line 1821, in handle_user_exception
    reraise(exc_type, exc_value, tb)
  File "/home/lean/Arhat/venv/lib/python3.7/site-packages/flask/_compat.py", line 39, in reraise
    raise value
  File "/home/lean/Arhat/venv/lib/python3.7/site-packages/flask/app.py", line 1950, in full_dispatch_request
    rv = self.dispatch_request()
  File "/home/lean/Arhat/venv/lib/python3.7/site-packages/flask/app.py", line 1936, in dispatch_request
    return self.view_functions[rule.endpoint](**req.view_args)
  File "/home/lean/Arhat/app/api/users.py", line 152, in create_task
    data = User.to_collection_dict(user.get_daily_tasks(date), None, None, None)
  File "/home/lean/Arhat/app/models.py", line 449, in get_daily_tasks
    date = datetime.strptime(date, "%d-%m-%Y")
  File "/usr/lib/python3.7/_strptime.py", line 577, in _strptime_datetime
    tt, fraction, gmtoff_fraction = _strptime(data_string, format)
  File "/usr/lib/python3.7/_strptime.py", line 359, in _strptime
    (data_string, format))
ValueError: time data '2020-06-06, 00:00:00' does not match format '%d-%m-%Y'
2020-05-30 17:43:34,312 INFO: 
            Template startup [in /home/lean/Arhat/app/__init__.py:
            97]
            
